Workbook

Sheet Read me
A1: Harbour Market — protein ratio (DEMO)
A2: FICTITIOUS DATA — demo file. Harbour Market, its brands and every figure are invented.
A4: What this file is | B4: An example of the workbook Altera AI delivers. It is built from an invented catalogue of 800 products and exists only to show the structure of a real deliverable.
A6: How to use it | B6: The yellow column 'Units sold (INPUT)' on the Products sheet is the only input. Change a volume and every figure on the Protein Tracker and WWF sheets recalculates.
A8: Protein Tracker | B8: Green Protein Alliance / ProVeg methodology. Tonnes of protein, split plant / animal. Level A: the split is measured. Level B: it follows the class or the 50/50 convention.
A10: WWF Planet-Based Diets | B10: Tonnes of product. Whole products by food group, composites by category. FG2 in dairy equivalents (hard and soft cheese x10). Appendix A exclusions apply.
A12: Scope | B12: Measured: 784 products sold over the year. Left out: 11 non-food items, 2 test items, 3 products without sales. WWF scope: alcohol, beverages other than dairy, coffee and tea, herbs and spices, condiments and stock excluded (Appendix A).
A14: Sources of each value | B14: Every protein value and every split carries its source in its own column.

Sheet Products
A1: FICTITIOUS DATA — demo file. Harbour Market, its brands and every figure are invented.
A2: Product ID | B2: Code | C2: Till label | D2: Product name | E2: Brand | F2: Department | G2: Family | H2: In scope | I2: PT class | J2: Data level | K2: Split source | L2: Protein g/100g | M2: Protein source | N2: Plant protein g/100g | O2: Animal protein g/100g | P2: WWF in scope | Q2: WWF structure | R2: Food group | S2: WWF sub-group | T2: WWF origin | U2: Composite category | V2: WWF exclusion | W2: Dairy factor | X2: Net weight kg | Y2: Weight source | Z2: Units sold (INPUT) | AA2: Mass kg | AB2: Protein kg | AC2: Plant protein kg | AD2: Animal protein kg | AE2: WWF tonnes | AF2: WWF tonnes, dairy eq.
A3: HM00001 | B3: 3012345357746 | C3: HM MILK CHOC BAR 4X40G | D3: Milk chocolate bar, 4x40g | E3: Harbour Market | F3: Breakfast & Snacks | G3: Chocolate | H3: yes | I3: Animal & plant composite | J3: A | K3: Ingredient list | L3: 7.7 | M3: Declared by the retailer | N3: 3.54 | O3: 4.16 | P3: yes | Q3: whole | R3: FG7 | T3: plant | W3: 1 | X3: 0.16 | Y3: declared | Z3: 7595 | AA3: =IF(H3="yes",Z3*X3,0) | AB3: =IF(H3="yes",AA3*N(L3)/100,0) | AC3: =IF(H3="yes",AA3*N(N3)/100,0) | AD3: =IF(H3="yes",AA3*N(O3)/100,0) | AE3: =IF(P3="yes",AA3/1000,0) | AF3: =IF(R3="FG2",AE3*W3,AE3)
A4: HM00002 | B4: 5012345864327 | C4: HM CHKN BREAST FLT 500G | D4: Chicken breast fillets, 500g | E4: Harbour Market | F4: Fresh Meat & Poultry | G4: Poultry | H4: yes | I4: Animal core | J4: B | K4: Follows the class | L4: 25 | M4: Name match (CIQUAL / NEVO) | N4: 0 | O4: 25 | P4: yes | Q4: whole | R4: FG1 | S4: poultry | T4: animal | W4: 1 | X4: 0.5 | Y4: declared | Z4: 31433 | AA4: =IF(H4="yes",Z4*X4,0) | AB4: =IF(H4="yes",AA4*N(L4)/100,0) | AC4: =IF(H4="yes",AA4*N(N4)/100,0) | AD4: =IF(H4="yes",AA4*N(O4)/100,0) | AE4: =IF(P4="yes",AA4/1000,0) | AF4: =IF(R4="FG2",AE4*W4,AE4)
A5: HM00003 | B5: 8712345464387 | C5: PENROCK SALTED PEANUTS 100G | D5: Salted peanuts, 100g | E5: Penrock | F5: Grocery | G5: Nuts & Seeds | H5: yes | I5: Plant-based core | J5: A | K5: All ingredients on one side | L5: 25.1 | M5: Declared by the retailer | N5: 25.1 | O5: 0 | P5: yes | Q5: whole | R5: FG1 | S5: nuts | T5: plant | W5: 1 | X5: 0.1 | Y5: declared | Z5: 16037 | AA5: =IF(H5="yes",Z5*X5,0) | AB5: =IF(H5="yes",AA5*N(L5)/100,0) | AC5: =IF(H5="yes",AA5*N(N5)/100,0) | AD5: =IF(H5="yes",AA5*N(O5)/100,0) | AE5: =IF(P5="yes",AA5/1000,0) | AF5: =IF(R5="FG2",AE5*W5,AE5)
A6: HM00004 | B6: 4012345136876 | C6: HM CUCUMBER EACH | D6: Cucumber | E6: Harbour Market | F6: Fruit & Vegetables | G6: Vegetables | H6: yes | I6: Plant-based non-core | J6: B | K6: Follows the class | L6: 0.59 | M6: Median of the family | N6: 0.59 | O6: 0 | P6: yes | Q6: whole | R6: FG4 | T6: plant | W6: 1 | X6: 0.35 | Y6: typical_piece | Z6: 59748 | AA6: =IF(H6="yes",Z6*X6,0) | AB6: =IF(H6="yes",AA6*N(L6)/100,0) | AC6: =IF(H6="yes",AA6*N(N6)/100,0) | AD6: =IF(H6="yes",AA6*N(O6)/100,0) | AE6: =IF(P6="yes",AA6/1000,0) | AF6: =IF(R6="FG2",AE6*W6,AE6)
A7: HM00005 | B7: 4012345806564 | C7: ORVALIS BLACK BEANS 4X400G | D7: Black beans in water, 4x400g | E7: Orvalis | F7: Grocery | G7: Pulses | H7: yes | I7: Plant-based core | J7: A | K7: All ingredients on one side | L7: 7 | M7: Median of the family | N7: 7 | O7: 0 | P7: yes | Q7: whole | R7: FG1 | S7: pulses | T7: plant | W7: 1 | X7: 1.6 | Y7: declared | Z7: 17242 | AA7: =IF(H7="yes",Z7*X7,0) | AB7: =IF(H7="yes",AA7*N(L7)/100,0) | AC7: =IF(H7="yes",AA7*N(N7)/100,0) | AD7: =IF(H7="yes",AA7*N(O7)/100,0) | AE7: =IF(P7="yes",AA7/1000,0) | AF7: =IF(R7="FG2",AE7*W7,AE7)
A8: HM00006 | B8: 4012345549430 | C8: HM COD FISH FINGERS 4PK 440G | D8: Cod fish fingers, 4pk 440g | E8: Harbour Market | F8: Frozen | G8: Frozen Fish | H8: yes | I8: Animal core | J8: B | K8: First ingredient (step 4a) | L8: 11.6 | M8: Declared by the retailer | N8: 0 | O8: 11.6 | P8: yes | Q8: whole | R8: FG1 | S8: fish shellfish | T8: animal | W8: 1 | X8: 0.44 | Y8: declared | Z8: 38088 | AA8: =IF(H8="yes",Z8*X8,0) | AB8: =IF(H8="yes",AA8*N(L8)/100,0) | AC8: =IF(H8="yes",AA8*N(N8)/100,0) | AD8: =IF(H8="yes",AA8*N(O8)/100,0) | AE8: =IF(P8="yes",AA8/1000,0) | AF8: =IF(R8="FG2",AE8*W8,AE8)
A9: HM00007 | B9: 2172222284030 | C9: HM CONFERENCE PEARS LOOSE | D9: Conference pears | E9: Harbour Market | F9: Fruit & Vegetables | G9: Fruit | H9: yes | I9: Plant-based non-core | J9: B | K9: Follows the class | L9: 0.39 | M9: Declared by the retailer | N9: 0.39 | O9: 0 | P9: yes | Q9: whole | R9: FG4 | T9: plant | W9: 1 | X9: 1 | Y9: variable | Z9: 11976 | AA9: =IF(H9="yes",Z9*X9,0) | AB9: =IF(H9="yes",AA9*N(L9)/100,0) | AC9: =IF(H9="yes",AA9*N(N9)/100,0) | AD9: =IF(H9="yes",AA9*N(O9)/100,0) | AE9: =IF(P9="yes",AA9/1000,0) | AF9: =IF(R9="FG2",AE9*W9,AE9)
A10: HM00008 | B10: 3012345602952 | C10: BBQ PORK RIBS MARIN 700G TARROW | D10: Marinated BBQ pork ribs, 700g | E10: Tarrow Farm | F10: Fresh Meat & Poultry | G10: BBQ & Marinated | H10: yes | I10: Animal core | J10: B | K10: First ingredient (step 4a) | L10: 16.7 | M10: Median of the family | N10: 0 | O10: 16.7 | P10: yes | Q10: whole | R10: FG1 | S10: red meat | T10: animal | W10: 1 | X10: 0.7 | Y10: declared | Z10: 45180 | AA10: =IF(H10="yes",Z10*X10,0) | AB10: =IF(H10="yes",AA10*N(L10)/100,0) | AC10: =IF(H10="yes",AA10*N(N10)/100,0) | AD10: =IF(H10="yes",AA10*N(O10)/100,0) | AE10: =IF(P10="yes",AA10/1000,0) | AF10: =IF(R10="FG2",AE10*W10,AE10)
A11: HM00009 | B11: 5012345329642 | C11: HM COURGETTES EACH | D11: Courgettes | E11: Harbour Market | F11: Fruit & Vegetables | G11: Vegetables | H11: yes | I11: Plant-based non-core | J11: B | K11: Follows the class | L11: 1.7 | M11: Altera reference base | N11: 1.7 | O11: 0 | P11: yes | Q11: whole | R11: FG4 | T11: plant | W11: 1 | X11: 0.25 | Y11: typical_piece | Z11: 62876 | AA11: =IF(H11="yes",Z11*X11,0) | AB11: =IF(H11="yes",AA11*N(L11)/100,0) | AC11: =IF(H11="yes",AA11*N(N11)/100,0) | AD11: =IF(H11="yes",AA11*N(O11)/100,0) | AE11: =IF(P11="yes",AA11/1000,0) | AF11: =IF(R11="FG2",AE11*W11,AE11)
A12: HM00010 | B12: 4012345408249 | C12: HM WHITE POTATOES 750G | D12: White potatoes, 750g | E12: Harbour Market | F12: Fruit & Vegetables | G12: Potatoes | H12: yes | I12: Plant-based non-core | J12: B | K12: Follows the class | L12: 1.9 | M12: Open Food Facts, by EAN | N12: 1.9 | O12: 0 | P12: yes | Q12: whole | R12: FG6 | T12: plant | W12: 1 | X12: 0.75 | Y12: declared | Z12: 39256 | AA12: =IF(H12="yes",Z12*X12,0) | AB12: =IF(H12="yes",AA12*N(L12)/100,0) | AC12: =IF(H12="yes",AA12*N(N12)/100,0) | AD12: =IF(H12="yes",AA12*N(O12)/100,0) | AE12: =IF(P12="yes",AA12/1000,0) | AF12: =IF(R12="FG2",AE12*W12,AE12)
A13: HM00011 | B13: 4012345434316 | C13: CHERRY YOG 450G FJELDA | D13: Cherry yoghurt, 450g | E13: Fjelda | F13: Dairy & Eggs | G13: Yoghurt | H13: yes | I13: Animal core | J13: B | K13: First ingredient (step 4a) | L13: 3.5 | M13: Altera reference base | N13: 0 | O13: 3.5 | P13: yes | Q13: whole | R13: FG2 | S13: dairy | T13: animal | W13: 1 | X13: 0.45 | Y13: label | Z13: 20236 | AA13: =IF(H13="yes",Z13*X13,0) | AB13: =IF(H13="yes",AA13*N(L13)/100,0) | AC13: =IF(H13="yes",AA13*N(N13)/100,0) | AD13: =IF(H13="yes",AA13*N(O13)/100,0) | AE13: =IF(P13="yes",AA13/1000,0) | AF13: =IF(R13="FG2",AE13*W13,AE13)
A14: HM00012 | B14: 5012345518169 | C14: HM BF MINCE 20% 400G | D14: Beef mince, 20% fat, 400g | E14: Harbour Market | F14: Fresh Meat & Poultry | G14: Beef | H14: yes | I14: Animal core | J14: A | K14: All ingredients on one side | L14: 17.8 | M14: Open Food Facts, by EAN | N14: 0 | O14: 17.8 | P14: yes | Q14: whole | R14: FG1 | S14: red meat | T14: animal | W14: 1 | X14: 0.4 | Y14: declared | Z14: 95677 | AA14: =IF(H14="yes",Z14*X14,0) | AB14: =IF(H14="yes",AA14*N(L14)/100,0) | AC14: =IF(H14="yes",AA14*N(N14)/100,0) | AD14: =IF(H14="yes",AA14*N(O14)/100,0) | AE14: =IF(P14="yes",AA14/1000,0) | AF14: =IF(R14="FG2",AE14*W14,AE14)
A15: HM00013 | B15: 5012345596600 | C15: HM BRIOCHE ROLLS 6PK 270G | D15: Brioche rolls, 6pk 270g | E15: Harbour Market | F15: Bakery | G15: Pastries | H15: yes | I15: Animal & plant composite | J15: B | K15: 50/50 convention | L15: 7.8 | M15: Declared by the retailer | N15: 3.9 | O15: 3.9 | P15: yes | Q15: whole | R15: FG7 | T15: plant | W15: 1 | X15: 0.27 | Y15: declared | Z15: 28283 | AA15: =IF(H15="yes",Z15*X15,0) | AB15: =IF(H15="yes",AA15*N(L15)/100,0) | AC15: =IF(H15="yes",AA15*N(N15)/100,0) | AD15: =IF(H15="yes",AA15*N(O15)/100,0) | AE15: =IF(P15="yes",AA15/1000,0) | AF15: =IF(R15="FG2",AE15*W15,AE15)
A16: HM00014 | B16: 8712345015398 | C16: HM CHORIZO SLICES 70G | D16: Chorizo slices, 70g | E16: Harbour Market | F16: Deli | G16: Cured Meats | H16: yes | I16: Animal core | J16: A | K16: All ingredients on one side | L16: 24.5 | M16: Declared by the retailer | N16: 0 | O16: 24.5 | P16: yes | Q16: whole | R16: FG1 | S16: red meat | T16: animal | W16: 1 | X16: 0.07 | Y16: declared | Z16: 42024 | AA16: =IF(H16="yes",Z16*X16,0) | AB16: =IF(H16="yes",AA16*N(L16)/100,0) | AC16: =IF(H16="yes",AA16*N(N16)/100,0) | AD16: =IF(H16="yes",AA16*N(O16)/100,0) | AE16: =IF(P16="yes",AA16/1000,0) | AF16: =IF(R16="FG2",AE16*W16,AE16)
A17: HM00015 | B17: 4012345189018 | C17: HM BLACK PEPPER GROUND 100G | D17: Ground black pepper, 100g | E17: Harbour Market | F17: Grocery | G17: Herbs & Spices | H17: yes | I17: Plant-based non-core | J17: B | K17: Follows the class | L17: 9.8 | M17: Median of the family | N17: 9.8 | O17: 0 | P17: no | V17: herbs spices | W17: 1 | X17: 0.1 | Y17: declared | Z17: 2863 | AA17: =IF(H17="yes",Z17*X17,0) | AB17: =IF(H17="yes",AA17*N(L17)/100,0) | AC17: =IF(H17="yes",AA17*N(N17)/100,0) | AD17: =IF(H17="yes",AA17*N(O17)/100,0) | AE17: =IF(P17="yes",AA17/1000,0) | AF17: =IF(R17="FG2",AE17*W17,AE17)
A18: HM00016 | B18: 5012345976006 | C18: HM NUT CHOC BARS 5X35G | D18: Nut & dark chocolate bars, 5x35g | E18: Harbour Market | F18: Breakfast & Snacks | G18: Cereal Bars | H18: yes | I18: Plant-based non-core | J18: B | K18: Follows the class | L18: 6.2 | M18: Declared by the retailer | N18: 6.2 | O18: 0 | P18: yes | Q18: whole | R18: FG7 | T18: plant | W18: 1 | X18: 0.175 | Y18: declared | Z18: 166857 | AA18: =IF(H18="yes",Z18*X18,0) | AB18: =IF(H18="yes",AA18*N(L18)/100,0) | AC18: =IF(H18="yes",AA18*N(N18)/100,0) | AD18: =IF(H18="yes",AA18*N(O18)/100,0) | AE18: =IF(P18="yes",AA18/1000,0) | AF18: =IF(R18="FG2",AE18*W18,AE18)
A19: HM00017 | B19: 4012345124340 | C19: HM APPLES PINK LADY 6PK | D19: Pink Lady apples, 6pk | E19: Harbour Market | F19: Fruit & Vegetables | G19: Fruit | H19: yes | I19: Plant-based non-core | J19: B | K19: Follows the class | L19: 0.3 | M19: Declared by the retailer | N19: 0.3 | O19: 0 | P19: yes | Q19: whole | R19: FG4 | T19: plant | W19: 1 | X19: 0.9 | Y19: declared | Z19: 88505 | AA19: =IF(H19="yes",Z19*X19,0) | AB19: =IF(H19="yes",AA19*N(L19)/100,0) | AC19: =IF(H19="yes",AA19*N(N19)/100,0) | AD19: =IF(H19="yes",AA19*N(O19)/100,0) | AE19: =IF(P19="yes",AA19/1000,0) | AF19: =IF(R19="FG2",AE19*W19,AE19)
A20: HM00018 | B20: 8712345317010 | C20: HM OAT RAISIN BARS 5X35G | D20: Oat & raisin bars, 5x35g | E20: Harbour Market | F20: Breakfast & Snacks | G20: Cereal Bars | H20: yes | I20: Plant-based non-core | J20: A | K20: All ingredients on one side | L20: 5.7 | M20: Declared by the retailer | N20: 5.7 | O20: 0 | P20: yes | Q20: whole | R20: FG7 | T20: plant | W20: 1 | X20: 0.175 | Y20: declared | Z20: 8680 | AA20: =IF(H20="yes",Z20*X20,0) | AB20: =IF(H20="yes",AA20*N(L20)/100,0) | AC20: =IF(H20="yes",AA20*N(N20)/100,0) | AD20: =IF(H20="yes",AA20*N(O20)/100,0) | AE20: =IF(P20="yes",AA20/1000,0) | AF20: =IF(R20="FG2",AE20*W20,AE20)
A21: HM00019 | B21: 8712345435639 | C21: HM CHOC CHIP COOKIES 200G | D21: Chocolate chip cookies, 200g | E21: Harbour Market | F21: Breakfast & Snacks | G21: Biscuits | H21: yes | I21: Animal & plant composite | J21: B | K21: 50/50 convention | L21: 6.4 | M21: Declared by the retailer | N21: 3.2 | O21: 3.2 | P21: yes | Q21: whole | R21: FG7 | T21: plant | W21: 1 | X21: 0.2 | Y21: declared | Z21: 177702 | AA21: =IF(H21="yes",Z21*X21,0) | AB21: =IF(H21="yes",AA21*N(L21)/100,0) | AC21: =IF(H21="yes",AA21*N(N21)/100,0) | AD21: =IF(H21="yes",AA21*N(O21)/100,0) | AE21: =IF(P21="yes",AA21/1000,0) | AF21: =IF(R21="FG2",AE21*W21,AE21)
A22: HM00020 | B22: 8712345090920 | C22: HM SMKD TOFU 200G | D22: Smoked tofu, 200g | E22: Harbour Market | F22: Plant-Based | G22: Tofu & Tempeh | H22: yes | I22: Plant-based core | J22: B | K22: Follows the class | L22: 12.5 | M22: Open Food Facts, by EAN | N22: 12.5 | O22: 0 | P22: yes | Q22: whole | R22: FG1 | S22: tofu tempeh seitan | T22: plant | W22: 1 | X22: 0.2 | Y22: declared | Z22: 16130 | AA22: =IF(H22="yes",Z22*X22,0) | AB22: =IF(H22="yes",AA22*N(L22)/100,0) | AC22: =IF(H22="yes",AA22*N(N22)/100,0) | AD22: =IF(H22="yes",AA22*N(O22)/100,0) | AE22: =IF(P22="yes",AA22/1000,0) | AF22: =IF(R22="FG2",AE22*W22,AE22)
A23: HM00021 | B23: 0012345871504 | C23: HM MILK CHOC HAZELNUT 4X40G | D23: Milk chocolate with hazelnuts, 4x40g | E23: Harbour Market | F23: Breakfast & Snacks | G23: Chocolate | H23: yes | I23: Animal & plant composite | J23: A | K23: Ingredient list | L23: 7.8 | M23: Declared by the retailer | N23: 3.59 | O23: 4.21 | P23: yes | Q23: whole | R23: FG7 | T23: plant | W23: 1 | X23: 0.16 | Y23: declared | Z23: 41407 | AA23: =IF(H23="yes",Z23*X23,0) | AB23: =IF(H23="yes",AA23*N(L23)/100,0) | AC23: =IF(H23="yes",AA23*N(N23)/100,0) | AD23: =IF(H23="yes",AA23*N(O23)/100,0) | AE23: =IF(P23="yes",AA23/1000,0) | AF23: =IF(R23="FG2",AE23*W23,AE23)
A24: HM00022 | B24: 5012345520179 | C24: HM RAPESEED OIL 1L | D24: Rapeseed oil, 1l | E24: Harbour Market | F24: Grocery | G24: Oils | H24: yes | I24: Plant-based non-core | J24: B | K24: Follows the class | L24: 0 | M24: Median of the family | N24: 0 | O24: 0 | P24: yes | Q24: whole | R24: FG3 | S24: plant fat | T24: plant | W24: 1 | X24: 0.92 | Y24: label | Z24: 8930 | AA24: =IF(H24="yes",Z24*X24,0) | AB24: =IF(H24="yes",AA24*N(L24)/100,0) | AC24: =IF(H24="yes",AA24*N(N24)/100,0) | AD24: =IF(H24="yes",AA24*N(O24)/100,0) | AE24: =IF(P24="yes",AA24/1000,0) | AF24: =IF(R24="FG2",AE24*W24,AE24)
A25: HM00023 | B25: 8712345602871 | C25: WHLWHT PENNE 1KG ORVALIS | D25: Wholewheat penne, 1kg | E25: Orvalis | F25: Grocery | G25: Pasta | H25: yes | I25: Plant-based non-core | J25: A | K25: All ingredients on one side | L25: 13.7 | M25: Declared by the retailer | N25: 13.7 | O25: 0 | P25: yes | Q25: whole | R25: FG5 | S25: whole grain | T25: plant | W25: 1 | X25: 1 | Y25: declared | Z25: 5102 | AA25: =IF(H25="yes",Z25*X25,0) | AB25: =IF(H25="yes",AA25*N(L25)/100,0) | AC25: =IF(H25="yes",AA25*N(N25)/100,0) | AD25: =IF(H25="yes",AA25*N(O25)/100,0) | AE25: =IF(P25="yes",AA25/1000,0) | AF25: =IF(R25="FG2",AE25*W25,AE25)
A26: HM00024 | B26: 5012345168616 | C26: HM CHERRY TOMATOES 300G | D26: Cherry tomatoes, 300g | E26: Harbour Market | F26: Fruit & Vegetables | G26: Vegetables | H26: yes | I26: Plant-based non-core | J26: B | K26: Follows the class | L26: 0.95 | M26: Declared by the retailer | N26: 0.95 | O26: 0 | P26: yes | Q26: whole | R26: FG4 | T26: plant | W26: 1 | X26: 0.3 | Y26: declared | Z26: 36495 | AA26: =IF(H26="yes",Z26*X26,0) | AB26: =IF(H26="yes",AA26*N(L26)/100,0) | AC26: =IF(H26="yes",AA26*N(N26)/100,0) | AD26: =IF(H26="yes",AA26*N(O26)/100,0) | AE26: =IF(P26="yes",AA26/1000,0) | AF26: =IF(R26="FG2",AE26*W26,AE26)
A27: HM00025 | B27: 3012345827010 | C27: HM EXTRA VIRGIN OLIVE OIL 500ML | D27: Extra virgin olive oil, 500ml | E27: Harbour Market | F27: Grocery | G27: Oils | H27: yes | I27: Plant-based non-core | J27: B | K27: Follows the class | L27: 0 | M27: Altera reference base | N27: 0 | O27: 0 | P27: yes | Q27: whole | R27: FG3 | S27: plant fat | T27: plant | W27: 1 | X27: 0.46 | Y27: declared | Z27: 17564 | AA27: =IF(H27="yes",Z27*X27,0) | AB27: =IF(H27="yes",AA27*N(L27)/100,0) | AC27: =IF(H27="yes",AA27*N(N27)/100,0) | AD27: =IF(H27="yes",AA27*N(O27)/100,0) | AE27: =IF(P27="yes",AA27/1000,0) | AF27: =IF(R27="FG2",AE27*W27,AE27)
A28: HM00026 | B28: 5012345615714 | C28: ALDERWICK EMMENTAL SLICES 10SL 250G | D28: Emmental slices, 10sl 250g | E28: Alderwick | F28: Cheese | G28: Hard Cheese | H28: yes | I28: Animal core | J28: A | K28: All ingredients on one side | L28: 27 | M28: Declared by the retailer | N28: 0 | O28: 27 | P28: yes | Q28: whole | R28: FG2 | S28: dairy | T28: animal | W28: 10 | X28: 0.25 | Y28: declared | Z28: 70533 | AA28: =IF(H28="yes",Z28*X28,0) | AB28: =IF(H28="yes",AA28*N(L28)/100,0) | AC28: =IF(H28="yes",AA28*N(N28)/100,0) | AD28: =IF(H28="yes",AA28*N(O28)/100,0) | AE28: =IF(P28="yes",AA28/1000,0) | AF28: =IF(R28="FG2",AE28*W28,AE28)
A29: HM00027 | B29: 4012345899306 | C29: HM CHICKPEAS IN WATER 400G | D29: Chickpeas in water, 400g | E29: Harbour Market | F29: Grocery | G29: Pulses | H29: yes | I29: Plant-based core | J29: B | K29: Follows the class | L29: 7.3 | M29: Declared by the retailer | N29: 7.3 | O29: 0 | P29: yes | Q29: whole | R29: FG1 | S29: pulses | T29: plant | W29: 1 | X29: 0.4 | Y29: declared | Z29: 15188 | AA29: =IF(H29="yes",Z29*X29,0) | AB29: =IF(H29="yes",AA29*N(L29)/100,0) | AC29: =IF(H29="yes",AA29*N(N29)/100,0) | AD29: =IF(H29="yes",AA29*N(O29)/100,0) | AE29: =IF(P29="yes",AA29/1000,0) | AF29: =IF(R29="FG2",AE29*W29,AE29)
A30: HM00028 | B30: 4012345640496 | C30: FJELDA SALTED BUTTER 500G | D30: Salted butter, 500g | E30: Fjelda | F30: Dairy & Eggs | G30: Butter & Spreads | H30: yes | I30: Animal core | J30: A | K30: All ingredients on one side | L30: 0.58 | M30: Median of the family | N30: 0 | O30: 0.58 | P30: yes | Q30: whole | R30: FG3 | S30: animal fat | T30: animal | W30: 1 | X30: 0.5 | Y30: declared | Z30: 13334 | AA30: =IF(H30="yes",Z30*X30,0) | AB30: =IF(H30="yes",AA30*N(L30)/100,0) | AC30: =IF(H30="yes",AA30*N(N30)/100,0) | AD30: =IF(H30="yes",AA30*N(O30)/100,0) | AE30: =IF(P30="yes",AA30/1000,0) | AF30: =IF(R30="FG2",AE30*W30,AE30)
A31: HM00029 | B31: 4012345849585 | C31: HM BABY SPINACH 1KG | D31: Baby spinach, 1kg | E31: Harbour Market | F31: Fruit & Vegetables | G31: Vegetables | H31: yes | I31: Plant-based non-core | J31: B | K31: Follows the class | L31: 2.9 | M31: Declared by the retailer | N31: 2.9 | O31: 0 | P31: yes | Q31: whole | R31: FG4 | T31: plant | W31: 1 | X31: 1 | Y31: declared | Z31: 24271 | AA31: =IF(H31="yes",Z31*X31,0) | AB31: =IF(H31="yes",AA31*N(L31)/100,0) | AC31: =IF(H31="yes",AA31*N(N31)/100,0) | AD31: =IF(H31="yes",AA31*N(O31)/100,0) | AE31: =IF(P31="yes",AA31/1000,0) | AF31: =IF(R31="FG2",AE31*W31,AE31)
A32: HM00030 | B32: 8712345591663 | C32: HM PLANT MINCE 400G | D32: Plant-based mince, 400g | E32: Harbour Market | F32: Plant-Based | G32: Meat Alternatives | H32: yes | I32: Plant-based core | J32: A | K32: All ingredients on one side | L32: 18 | M32: Altera reference base | N32: 18 | O32: 0 | P32: yes | Q32: whole | R32: FG1 | S32: alternative products | T32: plant | W32: 1 | X32: 0.4 | Y32: label | Z32: 7000 | AA32: =IF(H32="yes",Z32*X32,0) | AB32: =IF(H32="yes",AA32*N(L32)/100,0) | AC32: =IF(H32="yes",AA32*N(N32)/100,0) | AD32: =IF(H32="yes",AA32*N(O32)/100,0) | AE32: =IF(P32="yes",AA32/1000,0) | AF32: =IF(R32="FG2",AE32*W32,AE32)
A33: HM00031 | B33: 3012345216142 | C33: HM PORK LIVER PATE 2X85G | D33: Pork liver pâté, 2x85g | E33: Harbour Market | F33: Deli | G33: Pâté | H33: yes | I33: Animal core | J33: B | K33: Follows the class | L33: 12.5 | M33: Declared by the retailer | N33: 0 | O33: 12.5 | P33: yes | Q33: whole | R33: FG1 | S33: red meat | T33: animal | W33: 1 | X33: 0.17 | Y33: declared | Z33: 22699 | AA33: =IF(H33="yes",Z33*X33,0) | AB33: =IF(H33="yes",AA33*N(L33)/100,0) | AC33: =IF(H33="yes",AA33*N(N33)/100,0) | AD33: =IF(H33="yes",AA33*N(O33)/100,0) | AE33: =IF(P33="yes",AA33/1000,0) | AF33: =IF(R33="FG2",AE33*W33,AE33)
A34: HM00032 | B34: 4012345753233 | C34: ALDERWICK SOFT CHEESE PLAIN 250G | D34: Plain soft cheese, 250g | E34: Alderwick | F34: Cheese | G34: Fresh Cheese | H34: yes | I34: Animal core | J34: B | K34: Follows the class | L34: 6.9 | M34: Median of the family | N34: 0 | O34: 6.9 | P34: yes | Q34: whole | R34: FG2 | S34: dairy | T34: animal | W34: 1 | X34: 0.25 | Y34: declared | Z34: 9413 | AA34: =IF(H34="yes",Z34*X34,0) | AB34: =IF(H34="yes",AA34*N(L34)/100,0) | AC34: =IF(H34="yes",AA34*N(N34)/100,0) | AD34: =IF(H34="yes",AA34*N(O34)/100,0) | AE34: =IF(P34="yes",AA34/1000,0) | AF34: =IF(R34="FG2",AE34*W34,AE34)
A35: HM00033 | B35: 3012345311700 | C35: WHOLE ALMONDS 500G PENROCK | D35: Whole almonds, 500g | E35: Penrock | F35: Grocery | G35: Nuts & Seeds | H35: yes | I35: Plant-based core | J35: A | K35: All ingredients on one side | L35: 19.9 | M35: Declared by the retailer | N35: 19.9 | O35: 0 | P35: yes | Q35: whole | R35: FG1 | S35: nuts | T35: plant | W35: 1 | X35: 0.5 | Y35: declared | Z35: 12891 | AA35: =IF(H35="yes",Z35*X35,0) | AB35: =IF(H35="yes",AA35*N(L35)/100,0) | AC35: =IF(H35="yes",AA35*N(N35)/100,0) | AD35: =IF(H35="yes",AA35*N(O35)/100,0) | AE35: =IF(P35="yes",AA35/1000,0) | AF35: =IF(R35="FG2",AE35*W35,AE35)
A36: HM00034 | B36: 8712345337230 | C36: BRAMBLECOTE DIGESTIVE BISCUITS 300G | D36: Digestive biscuits, 300g | E36: Bramblecote | F36: Breakfast & Snacks | G36: Biscuits | H36: yes | I36: Plant-based non-core | J36: B | K36: Follows the class | L36: 7 | M36: Declared by the retailer | N36: 7 | O36: 0 | P36: yes | Q36: whole | R36: FG7 | T36: plant | W36: 1 | X36: 0.3 | Y36: declared | Z36: 11316 | AA36: =IF(H36="yes",Z36*X36,0) | AB36: =IF(H36="yes",AA36*N(L36)/100,0) | AC36: =IF(H36="yes",AA36*N(N36)/100,0) | AD36: =IF(H36="yes",AA36*N(O36)/100,0) | AE36: =IF(P36="yes",AA36/1000,0) | AF36: =IF(R36="FG2",AE36*W36,AE36)
A37: HM00035 | B37: 8712345755867 | C37: BRAMBLECOTE WHOLEMEAL SLICED 500G | D37: Wholemeal sliced bread, 500g | E37: Bramblecote | F37: Bakery | G37: Bread | H37: yes | I37: Plant-based non-core | J37: A | K37: All ingredients on one side | L37: 9.7 | M37: Declared by the retailer | N37: 9.7 | O37: 0 | P37: yes | Q37: whole | R37: FG5 | S37: whole grain | T37: plant | W37: 1 | X37: 0.5 | Y37: label | Z37: 34471 | AA37: =IF(H37="yes",Z37*X37,0) | AB37: =IF(H37="yes",AA37*N(L37)/100,0) | AC37: =IF(H37="yes",AA37*N(N37)/100,0) | AD37: =IF(H37="yes",AA37*N(O37)/100,0) | AE37: =IF(P37="yes",AA37/1000,0) | AF37: =IF(R37="FG2",AE37*W37,AE37)
A38: HM00036 | B38: 5012345424200 | C38: ORVALIS SPAGHETTI 3KG | D38: Spaghetti, 3kg | E38: Orvalis | F38: Grocery | G38: Pasta | H38: yes | I38: Plant-based non-core | J38: A | K38: All ingredients on one side | L38: 11.9 | M38: Median of the family | N38: 11.9 | O38: 0 | P38: yes | Q38: whole | R38: FG5 | S38: refined grain | T38: plant | W38: 1 | X38: 3 | Y38: label | Z38: 21102 | AA38: =IF(H38="yes",Z38*X38,0) | AB38: =IF(H38="yes",AA38*N(L38)/100,0) | AC38: =IF(H38="yes",AA38*N(N38)/100,0) | AD38: =IF(H38="yes",AA38*N(O38)/100,0) | AE38: =IF(P38="yes",AA38/1000,0) | AF38: =IF(R38="FG2",AE38*W38,AE38)
A39: HM00037 | B39: 5012345479453 | C39: HM SALMON FLT SKINLESS 240G | D39: Skinless salmon fillets, 240g | E39: Harbour Market | F39: Fish & Seafood | G39: Fresh Fish | H39: yes | I39: Animal core | J39: A | K39: All ingredients on one side | L39: 21.2 | M39: Declared by the retailer | N39: 0 | O39: 21.2 | P39: yes | Q39: whole | R39: FG1 | S39: fish shellfish | T39: animal | W39: 1 | X39: 0.24 | Y39: declared | Z39: 5295 | AA39: =IF(H39="yes",Z39*X39,0) | AB39: =IF(H39="yes",AA39*N(L39)/100,0) | AC39: =IF(H39="yes",AA39*N(N39)/100,0) | AD39: =IF(H39="yes",AA39*N(O39)/100,0) | AE39: =IF(P39="yes",AA39/1000,0) | AF39: =IF(R39="FG2",AE39*W39,AE39)
A40: HM00038 | B40: 4012345913798 | C40: PENNE RIGATE 500G ORVALIS | D40: Penne rigate, 500g | E40: Orvalis | F40: Grocery | G40: Pasta | H40: yes | I40: Plant-based non-core | J40: A | K40: All ingredients on one side | L40: 12.4 | M40: Declared by the retailer | N40: 12.4 | O40: 0 | P40: yes | Q40: whole | R40: FG5 | S40: refined grain | T40: plant | W40: 1 | X40: 0.5 | Y40: declared | Z40: 6122 | AA40: =IF(H40="yes",Z40*X40,0) | AB40: =IF(H40="yes",AA40*N(L40)/100,0) | AC40: =IF(H40="yes",AA40*N(N40)/100,0) | AD40: =IF(H40="yes",AA40*N(O40)/100,0) | AE40: =IF(P40="yes",AA40/1000,0) | AF40: =IF(R40="FG2",AE40*W40,AE40)
...

Sheet Protein Tracker
A1: Protein Tracker — plant share of protein sold
A2: FICTITIOUS DATA — demo file. Harbour Market, its brands and every figure are invented.
A4: Indicator | B4: Value
A5: Plant protein sold (t) | B5: =SUM(Products!$AC$3:$AC$802)/1000
A6: Animal protein sold (t) | B6: =SUM(Products!$AD$3:$AD$802)/1000
A7: Total protein sold (t) | B7: =SUM(Products!$AB$3:$AB$802)/1000
A8: Protein ratio — plant share | B8: =IFERROR(B5/B7,0)
A9: Protein measured at level A | B9: =IFERROR(SUMIFS(Products!$AB$3:$AB$802,Products!$J$3:$J$802,"A")/1000/B7,0)
A10: Check: plant + animal = total | B10: =IF(ABS(B5+B6-B7)<0.001,"OK","ERROR")
A13: PT class | B13: Protein (t) | C13: Share of protein
A14: Animal core | B14: =SUMIFS(Products!$AB$3:$AB$802,Products!$I$3:$I$802,A14)/1000 | C14: =IFERROR(B14/$B$7,0)
A15: Animal & plant composite | B15: =SUMIFS(Products!$AB$3:$AB$802,Products!$I$3:$I$802,A15)/1000 | C15: =IFERROR(B15/$B$7,0)
A16: Plant-based non-core | B16: =SUMIFS(Products!$AB$3:$AB$802,Products!$I$3:$I$802,A16)/1000 | C16: =IFERROR(B16/$B$7,0)
A17: Plant-based core | B17: =SUMIFS(Products!$AB$3:$AB$802,Products!$I$3:$I$802,A17)/1000 | C17: =IFERROR(B17/$B$7,0)
A18: Total | B18: =SUM(B14:B17) | C18: =IF(ABS(B18-B7)<0.001,"covers all classes","ERROR: a class is missing")
A20: Department | B20: Plant protein (t) | C20: Total protein (t) | D20: Plant share
A21: Bakery | B21: =SUMIFS(Products!$AC$3:$AC$802,Products!$F$3:$F$802,A21)/1000 | C21: =SUMIFS(Products!$AB$3:$AB$802,Products!$F$3:$F$802,A21)/1000 | D21: =IFERROR(B21/C21,0)
A22: Beer, Wine & Spirits | B22: =SUMIFS(Products!$AC$3:$AC$802,Products!$F$3:$F$802,A22)/1000 | C22: =SUMIFS(Products!$AB$3:$AB$802,Products!$F$3:$F$802,A22)/1000 | D22: =IFERROR(B22/C22,0)
A23: Breakfast & Snacks | B23: =SUMIFS(Products!$AC$3:$AC$802,Products!$F$3:$F$802,A23)/1000 | C23: =SUMIFS(Products!$AB$3:$AB$802,Products!$F$3:$F$802,A23)/1000 | D23: =IFERROR(B23/C23,0)
A24: Cheese | B24: =SUMIFS(Products!$AC$3:$AC$802,Products!$F$3:$F$802,A24)/1000 | C24: =SUMIFS(Products!$AB$3:$AB$802,Products!$F$3:$F$802,A24)/1000 | D24: =IFERROR(B24/C24,0)
A25: Dairy & Eggs | B25: =SUMIFS(Products!$AC$3:$AC$802,Products!$F$3:$F$802,A25)/1000 | C25: =SUMIFS(Products!$AB$3:$AB$802,Products!$F$3:$F$802,A25)/1000 | D25: =IFERROR(B25/C25,0)
A26: Deli | B26: =SUMIFS(Products!$AC$3:$AC$802,Products!$F$3:$F$802,A26)/1000 | C26: =SUMIFS(Products!$AB$3:$AB$802,Products!$F$3:$F$802,A26)/1000 | D26: =IFERROR(B26/C26,0)
A27: Fish & Seafood | B27: =SUMIFS(Products!$AC$3:$AC$802,Products!$F$3:$F$802,A27)/1000 | C27: =SUMIFS(Products!$AB$3:$AB$802,Products!$F$3:$F$802,A27)/1000 | D27: =IFERROR(B27/C27,0)
A28: Fresh Meat & Poultry | B28: =SUMIFS(Products!$AC$3:$AC$802,Products!$F$3:$F$802,A28)/1000 | C28: =SUMIFS(Products!$AB$3:$AB$802,Products!$F$3:$F$802,A28)/1000 | D28: =IFERROR(B28/C28,0)
A29: Frozen | B29: =SUMIFS(Products!$AC$3:$AC$802,Products!$F$3:$F$802,A29)/1000 | C29: =SUMIFS(Products!$AB$3:$AB$802,Products!$F$3:$F$802,A29)/1000 | D29: =IFERROR(B29/C29,0)
A30: Fruit & Vegetables | B30: =SUMIFS(Products!$AC$3:$AC$802,Products!$F$3:$F$802,A30)/1000 | C30: =SUMIFS(Products!$AB$3:$AB$802,Products!$F$3:$F$802,A30)/1000 | D30: =IFERROR(B30/C30,0)
A31: Grocery | B31: =SUMIFS(Products!$AC$3:$AC$802,Products!$F$3:$F$802,A31)/1000 | C31: =SUMIFS(Products!$AB$3:$AB$802,Products!$F$3:$F$802,A31)/1000 | D31: =IFERROR(B31/C31,0)
A32: Plant-Based | B32: =SUMIFS(Products!$AC$3:$AC$802,Products!$F$3:$F$802,A32)/1000 | C32: =SUMIFS(Products!$AB$3:$AB$802,Products!$F$3:$F$802,A32)/1000 | D32: =IFERROR(B32/C32,0)
... A34: Soft Drinks & Water | B34: =SUMIFS(Products!$AC$3:$AC$802,Products!$F$3:$F$802,A34)/1000 | C34: =SUMIFS(Products!$AB$3:$AB$802,Products!$F$3:$F$802,A34)/1000 | D34: =IFERROR(B34/C34,0)
A35: Total | C35: =SUM(C21:C34) | D35: =IF(ABS(C35-B7)<0.001,"covers all departments","ERROR: a department is missing")

Sheet WWF
A1: WWF Planet-Based Diets — tonnes of product
A2: FICTITIOUS DATA — demo file. Harbour Market, its brands and every figure are invented.
A4: Indicator | B4: Tonnes | C4: Share
A5: Whole products | B5: =SUMIFS(Products!$AE$3:$AE$802,Products!$Q$3:$Q$802,"whole") | C5: =IFERROR(B5/B7,0)
A6: Composite products | B6: =SUMIFS(Products!$AE$3:$AE$802,Products!$Q$3:$Q$802,"composite") | C6: =IFERROR(B6/B7,0)
A7: Total in WWF scope | B7: =B5+B6
A8: Outside the WWF scope (Appendix A) | B8: =SUMIFS(Products!$AA$3:$AA$802,Products!$H$3:$H$802,"yes",Products!$P$3:$P$802,"no")/1000
A10: Food group (whole products) | B10: Plant (t) | C10: Animal (t) | D10: Total (t) | E10: Plant share
A11: FG1 Protein-rich foods | B11: =SUMIFS(Products!$AF$3:$AF$802,Products!$Q$3:$Q$802,"whole",Products!$R$3:$R$802,F11,Products!$T$3:$T$802,"plant") | C11: =SUMIFS(Products!$AF$3:$AF$802,Products!$Q$3:$Q$802,"whole",Products!$R$3:$R$802,F11,Products!$T$3:$T$802,"animal") | D11: =B11+C11 | E11: =IFERROR(B11/D11,0) | F11: FG1
A12: FG2 Dairy & alternatives | B12: =SUMIFS(Products!$AF$3:$AF$802,Products!$Q$3:$Q$802,"whole",Products!$R$3:$R$802,F12,Products!$T$3:$T$802,"plant") | C12: =SUMIFS(Products!$AF$3:$AF$802,Products!$Q$3:$Q$802,"whole",Products!$R$3:$R$802,F12,Products!$T$3:$T$802,"animal") | D12: =B12+C12 | E12: =IFERROR(B12/D12,0) | F12: FG2
A13: FG3 Fats & oils | B13: =SUMIFS(Products!$AF$3:$AF$802,Products!$Q$3:$Q$802,"whole",Products!$R$3:$R$802,F13,Products!$T$3:$T$802,"plant") | C13: =SUMIFS(Products!$AF$3:$AF$802,Products!$Q$3:$Q$802,"whole",Products!$R$3:$R$802,F13,Products!$T$3:$T$802,"animal") | D13: =B13+C13 | E13: =IFERROR(B13/D13,0) | F13: FG3
A14: FG4 Fruit & vegetables | B14: =SUMIFS(Products!$AF$3:$AF$802,Products!$Q$3:$Q$802,"whole",Products!$R$3:$R$802,F14,Products!$T$3:$T$802,"plant") | C14: =SUMIFS(Products!$AF$3:$AF$802,Products!$Q$3:$Q$802,"whole",Products!$R$3:$R$802,F14,Products!$T$3:$T$802,"animal") | D14: =B14+C14 | E14: =IFERROR(B14/D14,0) | F14: FG4
A15: FG5 Grains & cereals | B15: =SUMIFS(Products!$AF$3:$AF$802,Products!$Q$3:$Q$802,"whole",Products!$R$3:$R$802,F15,Products!$T$3:$T$802,"plant") | C15: =SUMIFS(Products!$AF$3:$AF$802,Products!$Q$3:$Q$802,"whole",Products!$R$3:$R$802,F15,Products!$T$3:$T$802,"animal") | D15: =B15+C15 | E15: =IFERROR(B15/D15,0) | F15: FG5
A16: FG6 Tubers & starchy vegetables | B16: =SUMIFS(Products!$AF$3:$AF$802,Products!$Q$3:$Q$802,"whole",Products!$R$3:$R$802,F16,Products!$T$3:$T$802,"plant") | C16: =SUMIFS(Products!$AF$3:$AF$802,Products!$Q$3:$Q$802,"whole",Products!$R$3:$R$802,F16,Products!$T$3:$T$802,"animal") | D16: =B16+C16 | E16: =IFERROR(B16/D16,0) | F16: FG6
A17: FG7 Snacks high in fat, salt & sugar | B17: =SUMIFS(Products!$AF$3:$AF$802,Products!$Q$3:$Q$802,"whole",Products!$R$3:$R$802,F17,Products!$T$3:$T$802,"plant") | C17: =SUMIFS(Products!$AF$3:$AF$802,Products!$Q$3:$Q$802,"whole",Products!$R$3:$R$802,F17,Products!$T$3:$T$802,"animal") | D17: =B17+C17 | E17: =IFERROR(B17/D17,0) | F17: FG7
A18: FG2 in dairy equivalents: hard and soft cheese count x10.
A20: Plant share, FG1 + FG2 (mandatory split) | B20: =IFERROR((B11+B12)/(D11+D12),0)
A22: Composite category | B22: Tonnes | C22: Share of composites
A23: meat-based | B23: =SUMIFS(Products!$AE$3:$AE$802,Products!$Q$3:$Q$802,"composite",Products!$U$3:$U$802,A23) | C23: =IFERROR(B23/$B$6,0)
A24: seafood-based | B24: =SUMIFS(Products!$AE$3:$AE$802,Products!$Q$3:$Q$802,"composite",Products!$U$3:$U$802,A24) | C24: =IFERROR(B24/$B$6,0)
A25: vegetarian | B25: =SUMIFS(Products!$AE$3:$AE$802,Products!$Q$3:$Q$802,"composite",Products!$U$3:$U$802,A25) | C25: =IFERROR(B25/$B$6,0)
A26: vegan | B26: =SUMIFS(Products!$AE$3:$AE$802,Products!$Q$3:$Q$802,"composite",Products!$U$3:$U$802,A26) | C26: =IFERROR(B26/$B$6,0)
